Workbook

Sheet MASTER
A1: ISBN | B1: TITLE | C1: GRADE | D1: SUBJECT | E1: LANGUAGE | F1: PRICE | G1: PUBLISHER
A2: 9781920192228 | B2: Understanding Life Sciences Grade 10 – Learner’s Book (3rd edition - CAPS) | F2: 0 | G2: Pulse
A3: 9781920192235 | B3: Understanding Life Sciences Grade 10 – Teacher’s Guide (3rd edition - CAPS) | F3: 0 | G3: Pulse
A4: 9781920192266 | B4: Understanding Life Sciences Grade 11 – Learner’s Book (3rd edition - CAPS) | F4: 0 | G4: Pulse
A5: 9781920192273 | B5: Understanding Life Sciences Grade 11 – Teacher’s Guide (3rd edition - CAPS) | F5: 0 | G5: Pulse
A6: 9781920192280 | B6: Understanding Life Sciences Grade 12 – Learner’s Book (3rd edition - CAPS) | F6: 0 | G6: Pulse
A7: 9781920192297 | B7: Understanding Life Sciences Grade 12 – Teacher’s Guide (3rd edition - CAPS) | F7: 0 | G7: Pulse
A8: 9781920192242 | B8: Study Guide for Understanding Life Sciences including Questions and Answers - Grade 10 CAPS (3rd edition) | F8: 0 | G8: Pulse
A9: 9781920192327 | B9: Study Guide for Understanding Life Sciences - Grade 11 CAPS (3rd edition) | F9: 0 | G9: Pulse
A10: 9781920192303 | B10: Study Guide for Understanding Life Sciences including Questions and Answers - Grade 12 CAPS (3rd edition) | F10: 0 | G10: Pulse
A11: 9781920192310 | B11: Studiegids vir Verstaan Lewenswetenskappe insluitende Vrae & Antwoorde - Graad 12 | F11: 0 | G11: Pulse
A12: 9781920192259 | B12: Workbook for Understanding Life Sciences - Grade 12 CAPS | F12: 0 | G12: Pulse
A13: 9781920192990 | B13: Werkboek vir Verstaan Lewenswetenskappe - Graad 12 CAPS | F13: 0 | G13: Pulse
A14: 9780190402549 | B14: Oxford Kereiti ya R Buka ya puiso 1: Nna | C14: R | D14: Language | E14: Setswana | F14: 32.95 | G14: OXFORD
A15: 9780190408527 | B15: Oxford Kereiti ya R Buka ya puiso 2: Kwa sekolong | C15: R | D15: Language | E15: Setswana | F15: 32.95 | G15: OXFORD
A16: 9780190407179 | B16: Oxford Kereiti ya R Buka ya puiso 3: Phaposiborutelo | C16: R | D16: Language | E16: Setswana | F16: 32.95 | G16: OXFORD
A17: 9780190403447 | B17: Oxford Kereiti ya R Buka ya puiso 4: Dibuka | C17: R | D17: Language | E17: Setswana | F17: 32.95 | G17: OXFORD
A18: 9780199046935 | B18: Oxford Kereiti ya R Buka ya puiso 5: Malatsi a beke | C18: R | D18: Language | E18: Setswana | F18: 32.95 | G18: OXFORD
A19: 9780190403850 | B19: Oxford Kereiti ya R Buka ya puiso 6: Mmele wa me | C19: R | D19: Language | E19: Setswana | F19: 32.95 | G19: OXFORD
A20: 9780190402471 | B20: Oxford Kereiti ya R Buka ya puiso 7: Botshelo jo bo itekanetseng | C20: R | D20: Language | E20: Setswana | F20: 32.95 | G20: OXFORD
A21: 9780190403928 | B21: Oxford Kereiti ya R Buka ya puiso 8: Selemo | C21: R | D21: Language | E21: Setswana | F21: 32.95 | G21: OXFORD
A22: 9780199075133 | B22: Oxford Kereiti ya R Buka ya puiso 9: Dipopego le mebala | C22: R | D22: Language | E22: Setswana | F22: 32.95 | G22: OXFORD
A23: 9780190408480 | B23: Oxford Kereiti ya R Buka ya puiso 10: Leeto le le monate | C23: R | D23: Language | E23: Setswana | F23: 32.95 | G23: OXFORD
A24: 9780190405182 | B24: Oxford Kereiti ya R Buka ya puiso 11: Legae | C24: R | D24: Language | E24: Setswana | F24: 32.95 | G24: OXFORD
A25: 9780190400996 | B25: Oxford Kereiti ya R Buka ya puiso 12: Tshireletsego | C25: R | D25: Language | E25: Setswana | F25: 32.95 | G25: OXFORD
... A409: 9780195989618 | B409: We are growing Grade R Teacherʼs Book | C409: R | D409: Language | E409: English | F409: 505.95 | G409: OXFORD
A410: 9780195980240 | B410: We are growing Stage 1 Readers (Pack of 12) | D410: Language | E410: English | F410: 801.95 | G410: OXFORD
A411: 9780195980271 | B411: Big and Small | C411: 1 | D411: Language | E411: English | F411: 43.95 | G411: OXFORD
A412: 9780195980288 | B412: Play with me | C412: 1 | D412: Language | E412: English | F412: 43.95 | G412: OXFORD
A413: 9780195980295 | B413: Hands talk | C413: 1 | D413: Language | E413: English | F413: 43.95 | G413: OXFORD
A414: 9780195980301 | B414: The red ball | C414: 1 | D414: Language | E414: English | F414: 43.95 | G414: OXFORD
A415: 9780195980318 | B415: Look and listen | C415: 1 | D415: Language | E415: English | F415: 43.95 | G415: OXFORD
A416: 9780195980325 | B416: Count with me | C416: 1 | D416: Language | E416: English | F416: 43.95 | G416: OXFORD
A417: 9780195980332 | B417: Days | C417: 1 | D417: Language | E417: English | F417: 43.95 | G417: OXFORD
A418: 9780195980349 | B418: Fire | C418: 1 | D418: Language | E418: English | F418: 43.95 | G418: OXFORD
A419: 9780195980356 | B419: Food of many colours | C419: 1 | D419: Language | E419: English | F419: 43.95 | G419: OXFORD
A420: 9780195980363 | B420: Sleepy boy | C420: 1 | D420: Language | E420: English | F420: 43.95 | G420: OXFORD
A421: 9780195980370 | B421: Run, cat boy, run | C421: 1 | D421: Language | E421: English | F421: 43.95 | G421: OXFORD
A422: 9780195980387 | B422: My dreams | C422: 1 | D422: Language | E422: English | F422: 43.95 | G422: OXFORD
A423: 9780195988758 | B423: We are growing Stage 1 Big Book Big and Small The red ball Run, cat boy, run My dreams | D423: Language | E423: English | F423: 717.95 | G423: OXFORD
...

Sheet QUOTATION
A1: KALIKENG TRADING AND PROJECTS CC
A2: Reg No: 2010/007041/23 | VAT No: 4340257320 | Tel: 073 223 9762 | kalikengtrading@gmail.com
A3: B-BBEE LEVEL 1 | 100% BLACK OWNED | 135% PROCUREMENT RECOGNITION
A6: QUOTATION NO: | E6: DATE:
A7: SCHOOL / CLIENT: | E7: PREPARED BY:
A8: ADDRESS: | E8: PHONE:
A10: ISBN | B10: TITLE | C10: GR | D10: SUBJECT | E10: LANGUAGE | F10: PUBLISHER | G10: UNIT PRICE | H10: QTY | I10: LINE TOTAL
B11: =IFERROR(VLOOKUP(A11,MASTER!$A:$G,2,0),"") | C11: =IFERROR(VLOOKUP(A11,MASTER!$A:$G,3,0),"") | D11: =IFERROR(VLOOKUP(A11,MASTER!$A:$G,4,0),"") | E11: =IFERROR(VLOOKUP(A11,MASTER!$A:$G,5,0),"") | F11: =IFERROR(VLOOKUP(A11,MASTER!$A:$G,7,0),"") | G11: =IFERROR(VLOOKUP(A11,MASTER!$A:$G,6,0),"") | I11: =IFERROR(IF(H11="","",G11*H11),"")
B12: =IFERROR(VLOOKUP(A12,MASTER!$A:$G,2,0),"") | C12: =IFERROR(VLOOKUP(A12,MASTER!$A:$G,3,0),"") | D12: =IFERROR(VLOOKUP(A12,MASTER!$A:$G,4,0),"") | E12: =IFERROR(VLOOKUP(A12,MASTER!$A:$G,5,0),"") | F12: =IFERROR(VLOOKUP(A12,MASTER!$A:$G,7,0),"") | G12: =IFERROR(VLOOKUP(A12,MASTER!$A:$G,6,0),"") | I12: =IFERROR(IF(H12="","",G12*H12),"")
B13: =IFERROR(VLOOKUP(A13,MASTER!$A:$G,2,0),"") | C13: =IFERROR(VLOOKUP(A13,MASTER!$A:$G,3,0),"") | D13: =IFERROR(VLOOKUP(A13,MASTER!$A:$G,4,0),"") | E13: =IFERROR(VLOOKUP(A13,MASTER!$A:$G,5,0),"") | F13: =IFERROR(VLOOKUP(A13,MASTER!$A:$G,7,0),"") | G13: =IFERROR(VLOOKUP(A13,MASTER!$A:$G,6,0),"") | I13: =IFERROR(IF(H13="","",G13*H13),"")
B14: =IFERROR(VLOOKUP(A14,MASTER!$A:$G,2,0),"") | C14: =IFERROR(VLOOKUP(A14,MASTER!$A:$G,3,0),"") | D14: =IFERROR(VLOOKUP(A14,MASTER!$A:$G,4,0),"") | E14: =IFERROR(VLOOKUP(A14,MASTER!$A:$G,5,0),"") | F14: =IFERROR(VLOOKUP(A14,MASTER!$A:$G,7,0),"") | G14: =IFERROR(VLOOKUP(A14,MASTER!$A:$G,6,0),"") | I14: =IFERROR(IF(H14="","",G14*H14),"")
B15: =IFERROR(VLOOKUP(A15,MASTER!$A:$G,2,0),"") | C15: =IFERROR(VLOOKUP(A15,MASTER!$A:$G,3,0),"") | D15: =IFERROR(VLOOKUP(A15,MASTER!$A:$G,4,0),"") | E15: =IFERROR(VLOOKUP(A15,MASTER!$A:$G,5,0),"") | F15: =IFERROR(VLOOKUP(A15,MASTER!$A:$G,7,0),"") | G15: =IFERROR(VLOOKUP(A15,MASTER!$A:$G,6,0),"") | I15: =IFERROR(IF(H15="","",G15*H15),"")
B16: =IFERROR(VLOOKUP(A16,MASTER!$A:$G,2,0),"") | C16: =IFERROR(VLOOKUP(A16,MASTER!$A:$G,3,0),"") | D16: =IFERROR(VLOOKUP(A16,MASTER!$A:$G,4,0),"") | E16: =IFERROR(VLOOKUP(A16,MASTER!$A:$G,5,0),"") | F16: =IFERROR(VLOOKUP(A16,MASTER!$A:$G,7,0),"") | G16: =IFERROR(VLOOKUP(A16,MASTER!$A:$G,6,0),"") | I16: =IFERROR(IF(H16="","",G16*H16),"")
B17: =IFERROR(VLOOKUP(A17,MASTER!$A:$G,2,0),"") | C17: =IFERROR(VLOOKUP(A17,MASTER!$A:$G,3,0),"") | D17: =IFERROR(VLOOKUP(A17,MASTER!$A:$G,4,0),"") | E17: =IFERROR(VLOOKUP(A17,MASTER!$A:$G,5,0),"") | F17: =IFERROR(VLOOKUP(A17,MASTER!$A:$G,7,0),"") | G17: =IFERROR(VLOOKUP(A17,MASTER!$A:$G,6,0),"") | I17: =IFERROR(IF(H17="","",G17*H17),"")
B18: =IFERROR(VLOOKUP(A18,MASTER!$A:$G,2,0),"") | C18: =IFERROR(VLOOKUP(A18,MASTER!$A:$G,3,0),"") | D18: =IFERROR(VLOOKUP(A18,MASTER!$A:$G,4,0),"") | E18: =IFERROR(VLOOKUP(A18,MASTER!$A:$G,5,0),"") | F18: =IFERROR(VLOOKUP(A18,MASTER!$A:$G,7,0),"") | G18: =IFERROR(VLOOKUP(A18,MASTER!$A:$G,6,0),"") | I18: =IFERROR(IF(H18="","",G18*H18),"")
B19: =IFERROR(VLOOKUP(A19,MASTER!$A:$G,2,0),"") | C19: =IFERROR(VLOOKUP(A19,MASTER!$A:$G,3,0),"") | D19: =IFERROR(VLOOKUP(A19,MASTER!$A:$G,4,0),"") | E19: =IFERROR(VLOOKUP(A19,MASTER!$A:$G,5,0),"") | F19: =IFERROR(VLOOKUP(A19,MASTER!$A:$G,7,0),"") | G19: =IFERROR(VLOOKUP(A19,MASTER!$A:$G,6,0),"") | I19: =IFERROR(IF(H19="","",G19*H19),"")
B20: =IFERROR(VLOOKUP(A20,MASTER!$A:$G,2,0),"") | C20: =IFERROR(VLOOKUP(A20,MASTER!$A:$G,3,0),"") | D20: =IFERROR(VLOOKUP(A20,MASTER!$A:$G,4,0),"") | E20: =IFERROR(VLOOKUP(A20,MASTER!$A:$G,5,0),"") | F20: =IFERROR(VLOOKUP(A20,MASTER!$A:$G,7,0),"") | G20: =IFERROR(VLOOKUP(A20,MASTER!$A:$G,6,0),"") | I20: =IFERROR(IF(H20="","",G20*H20),"")
B21: =IFERROR(VLOOKUP(A21,MASTER!$A:$G,2,0),"") | C21: =IFERROR(VLOOKUP(A21,MASTER!$A:$G,3,0),"") | D21: =IFERROR(VLOOKUP(A21,MASTER!$A:$G,4,0),"") | E21: =IFERROR(VLOOKUP(A21,MASTER!$A:$G,5,0),"") | F21: =IFERROR(VLOOKUP(A21,MASTER!$A:$G,7,0),"") | G21: =IFERROR(VLOOKUP(A21,MASTER!$A:$G,6,0),"") | I21: =IFERROR(IF(H21="","",G21*H21),"")
B22: =IFERROR(VLOOKUP(A22,MASTER!$A:$G,2,0),"") | C22: =IFERROR(VLOOKUP(A22,MASTER!$A:$G,3,0),"") | D22: =IFERROR(VLOOKUP(A22,MASTER!$A:$G,4,0),"") | E22: =IFERROR(VLOOKUP(A22,MASTER!$A:$G,5,0),"") | F22: =IFERROR(VLOOKUP(A22,MASTER!$A:$G,7,0),"") | G22: =IFERROR(VLOOKUP(A22,MASTER!$A:$G,6,0),"") | I22: =IFERROR(IF(H22="","",G22*H22),"")
... B210: =IFERROR(VLOOKUP(A210,MASTER!$A:$G,2,0),"") | C210: =IFERROR(VLOOKUP(A210,MASTER!$A:$G,3,0),"") | D210: =IFERROR(VLOOKUP(A210,MASTER!$A:$G,4,0),"") | E210: =IFERROR(VLOOKUP(A210,MASTER!$A:$G,5,0),"") | F210: =IFERROR(VLOOKUP(A210,MASTER!$A:$G,7,0),"") | G210: =IFERROR(VLOOKUP(A210,MASTER!$A:$G,6,0),"") | I210: =IFERROR(IF(H210="","",G210*H210),"")
A211: GRAND TOTAL | I211: =IFERROR(SUM(I11:I210),0)
